Workbook

Sheet ACCUEIL
A1: Bienvenue sur le registre Exhaustif des Objets et Matériaux
A2: Que contient le registre ? | F2: Pourquoi deux pages ? | K2: Comment utiliser le registre ? | P2: Comment ça marche ?
A3: Ce registre contient 2 pages : "VENTES"qui contient l'ensemble des objets pouvant êtres fabriqués au métier à tisser, leur prix recommandé, les matériaux requis, la somme du prix des matériaux. "MATERIAUX" la liste des matériaux utilisés par la couture, les prix d'achats, et le prorata par la quantité | F3: Avoir 2 pages distinctes permet de retrouver plus facilement les objets et permet de structurer les calculs pour une utilisation plus facile | K3: Vous pouvez dans la page "VENTES" utiliser ctrl+f pour effectuer une recherche d'un objet souhaité. Vous pouvez dans la page "MATERIAUX" vérifier les prix de rachat classique | P3: La colonne "Cout de création" reprend les éléments précédents et effectue le calcul avec les prix présents dans la page matériaux en multipliant par la quantité nécessaire pour créer l'objet.
A16: J'espère que ce registre vous sera utile bon jeu à tous ^^
Q18: Réalisé par Ja'Zidir
Q20: Avec la participation de Za'Saad

Sheet VENTES
A1: Objet | B1: Prix de vente | C1: Marge | D1: % de marge | E1: Materiel 1 | F1: Quantitée 1 | G1: Materiel 2 | H1: Quantitée 2 | I1: Materiel 3 | J1: Quantitée 3 | K1: Materiel 4 | L1: Quantitée 4 | M1: Materiel 5 | N1: Quantitée 5 | O1: Materiel 6 | P1: Quantitée 6 | Q1: Cout de création
A2: Bandages de pieds | B2: 20 | C2: =B2-Q2 -> 19.666667 | D2: =(C2/Q2) -> 59 | E2: Fil | F2: 1 | Q2: =SUM( IFERROR(VLOOKUP(E2,MATERIAUX!$A$1:$D$27,4,FALSE)*F2,0), IFERROR(VLOOKUP(G2,MATERIAUX!$A$1:$D$27,4,FALSE)*H2,0), IFERROR(VLOOKUP(I2,MATERIAUX!$A$1:$D$27,4,FALSE)*J2,0), IFERROR(VLOOKUP(K2,MATERIAUX!$A$1:$D$27,4,FALSE)*L2,0), IFERROR(VLOOKUP(M2,MATERIAUX!$A$1:$D$27,4,FALSE)*N2,0), IFERROR(VLOOKUP(O2,MATERIAUX!$A$1:$D$27,4,FALSE)*P2,0) ) -> 0.33333333
A3: Bottes | B3: 20 | C3: =B3-Q3 -> 16.666667 | D3: =(C3/Q3) -> 5 | E3: Fil | F3: 1 | G3: Cuir | H3: 1 | Q3: =SUM( IFERROR(VLOOKUP(E3,MATERIAUX!$A$1:$D$27,4,FALSE)*F3,0), IFERROR(VLOOKUP(G3,MATERIAUX!$A$1:$D$27,4,FALSE)*H3,0), IFERROR(VLOOKUP(I3,MATERIAUX!$A$1:$D$27,4,FALSE)*J3,0), IFERROR(VLOOKUP(K3,MATERIAUX!$A$1:$D$27,4,FALSE)*L3,0), IFERROR(VLOOKUP(M3,MATERIAUX!$A$1:$D$27,4,FALSE)*N3,0), IFERROR(VLOOKUP(O3,MATERIAUX!$A$1:$D$27,4,FALSE)*P3,0) ) -> 3.3333333
A4: Bottes | B4: 20 | C4: =B4-Q4 -> 13.333333 | D4: =(C4/Q4) -> 2 | E4: Fil | F4: 2 | G4: Cuir | H4: 2 | Q4: =SUM( IFERROR(VLOOKUP(E4,MATERIAUX!$A$1:$D$27,4,FALSE)*F4,0), IFERROR(VLOOKUP(G4,MATERIAUX!$A$1:$D$27,4,FALSE)*H4,0), IFERROR(VLOOKUP(I4,MATERIAUX!$A$1:$D$27,4,FALSE)*J4,0), IFERROR(VLOOKUP(K4,MATERIAUX!$A$1:$D$27,4,FALSE)*L4,0), IFERROR(VLOOKUP(M4,MATERIAUX!$A$1:$D$27,4,FALSE)*N4,0), IFERROR(VLOOKUP(O4,MATERIAUX!$A$1:$D$27,4,FALSE)*P4,0) ) -> 6.6666667
A5: Bottes | B5: 20 | C5: =B5-Q5 -> 13.666667 | D5: =(C5/Q5) -> 2.1578947 | E5: Fil | F5: 1 | G5: Cuir | H5: 2 | Q5: =SUM( IFERROR(VLOOKUP(E5,MATERIAUX!$A$1:$D$27,4,FALSE)*F5,0), IFERROR(VLOOKUP(G5,MATERIAUX!$A$1:$D$27,4,FALSE)*H5,0), IFERROR(VLOOKUP(I5,MATERIAUX!$A$1:$D$27,4,FALSE)*J5,0), IFERROR(VLOOKUP(K5,MATERIAUX!$A$1:$D$27,4,FALSE)*L5,0), IFERROR(VLOOKUP(M5,MATERIAUX!$A$1:$D$27,4,FALSE)*N5,0), IFERROR(VLOOKUP(O5,MATERIAUX!$A$1:$D$27,4,FALSE)*P5,0) ) -> 6.3333333
A6: Bottes raffinées | B6: 20 | C6: =B6-Q6 -> 13 | D6: =(C6/Q6) -> 1.8571429 | E6: Fil | F6: 3 | G6: Cuir | H6: 2 | Q6: =SUM( IFERROR(VLOOKUP(E6,MATERIAUX!$A$1:$D$27,4,FALSE)*F6,0), IFERROR(VLOOKUP(G6,MATERIAUX!$A$1:$D$27,4,FALSE)*H6,0), IFERROR(VLOOKUP(I6,MATERIAUX!$A$1:$D$27,4,FALSE)*J6,0), IFERROR(VLOOKUP(K6,MATERIAUX!$A$1:$D$27,4,FALSE)*L6,0), IFERROR(VLOOKUP(M6,MATERIAUX!$A$1:$D$27,4,FALSE)*N6,0), IFERROR(VLOOKUP(O6,MATERIAUX!$A$1:$D$27,4,FALSE)*P6,0) ) -> 7
A7: Chaussures | B7: 20 | C7: =B7-Q7 -> 16.666667 | D7: =(C7/Q7) -> 5 | E7: Fil | F7: 1 | G7: Cuir | H7: 1 | Q7: =SUM( IFERROR(VLOOKUP(E7,MATERIAUX!$A$1:$D$27,4,FALSE)*F7,0), IFERROR(VLOOKUP(G7,MATERIAUX!$A$1:$D$27,4,FALSE)*H7,0), IFERROR(VLOOKUP(I7,MATERIAUX!$A$1:$D$27,4,FALSE)*J7,0), IFERROR(VLOOKUP(K7,MATERIAUX!$A$1:$D$27,4,FALSE)*L7,0), IFERROR(VLOOKUP(M7,MATERIAUX!$A$1:$D$27,4,FALSE)*N7,0), IFERROR(VLOOKUP(O7,MATERIAUX!$A$1:$D$27,4,FALSE)*P7,0) ) -> 3.3333333
A8: Priest Sandals | B8: 20 | C8: =B8-Q8 -> 13.333333 | D8: =(C8/Q8) -> 2 | E8: Fil | F8: 2 | G8: Cuir | H8: 2 | Q8: =SUM( IFERROR(VLOOKUP(E8,MATERIAUX!$A$1:$D$27,4,FALSE)*F8,0), IFERROR(VLOOKUP(G8,MATERIAUX!$A$1:$D$27,4,FALSE)*H8,0), IFERROR(VLOOKUP(I8,MATERIAUX!$A$1:$D$27,4,FALSE)*J8,0), IFERROR(VLOOKUP(K8,MATERIAUX!$A$1:$D$27,4,FALSE)*L8,0), IFERROR(VLOOKUP(M8,MATERIAUX!$A$1:$D$27,4,FALSE)*N8,0), IFERROR(VLOOKUP(O8,MATERIAUX!$A$1:$D$27,4,FALSE)*P8,0) ) -> 6.6666667
A9: Common Clothes | B9: 30 | C9: =B9-Q9 -> 26.9 | D9: =(C9/Q9) -> 8.6774194 | E9: Cuir | F9: 1 | G9: Coton | H9: 1 | Q9: =SUM( IFERROR(VLOOKUP(E9,MATERIAUX!$A$1:$D$27,4,FALSE)*F9,0), IFERROR(VLOOKUP(G9,MATERIAUX!$A$1:$D$27,4,FALSE)*H9,0), IFERROR(VLOOKUP(I9,MATERIAUX!$A$1:$D$27,4,FALSE)*J9,0), IFERROR(VLOOKUP(K9,MATERIAUX!$A$1:$D$27,4,FALSE)*L9,0), IFERROR(VLOOKUP(M9,MATERIAUX!$A$1:$D$27,4,FALSE)*N9,0), IFERROR(VLOOKUP(O9,MATERIAUX!$A$1:$D$27,4,FALSE)*P9,0) ) -> 3.1
A10: Common robes | B10: 30 | C10: =B10-Q10 -> 23.5 | D10: =(C10/Q10) -> 3.6153846 | E10: Cuir | F10: 2 | G10: Coton | H10: 5 | Q10: =SUM( IFERROR(VLOOKUP(E10,MATERIAUX!$A$1:$D$27,4,FALSE)*F10,0), IFERROR(VLOOKUP(G10,MATERIAUX!$A$1:$D$27,4,FALSE)*H10,0), IFERROR(VLOOKUP(I10,MATERIAUX!$A$1:$D$27,4,FALSE)*J10,0), IFERROR(VLOOKUP(K10,MATERIAUX!$A$1:$D$27,4,FALSE)*L10,0), IFERROR(VLOOKUP(M10,MATERIAUX!$A$1:$D$27,4,FALSE)*N10,0), IFERROR(VLOOKUP(O10,MATERIAUX!$A$1:$D$27,4,FALSE)*P10,0) ) -> 6.5
A11: Fine Clothes | B11: 40 | C11: =B11-Q11 -> 35.333333 | D11: =(C11/Q11) -> 7.5714286 | E11: Cuir | F11: 1 | G11: Fil | H11: 5 | Q11: =SUM( IFERROR(VLOOKUP(E11,MATERIAUX!$A$1:$D$27,4,FALSE)*F11,0), IFERROR(VLOOKUP(G11,MATERIAUX!$A$1:$D$27,4,FALSE)*H11,0), IFERROR(VLOOKUP(I11,MATERIAUX!$A$1:$D$27,4,FALSE)*J11,0), IFERROR(VLOOKUP(K11,MATERIAUX!$A$1:$D$27,4,FALSE)*L11,0), IFERROR(VLOOKUP(M11,MATERIAUX!$A$1:$D$27,4,FALSE)*N11,0), IFERROR(VLOOKUP(O11,MATERIAUX!$A$1:$D$27,4,FALSE)*P11,0) ) -> 4.6666667
A12: Fine Clothes Arcana | B12: 100 | C12: =B12-Q12 -> 60.666667 | D12: =(C12/Q12) -> 1.5423729 | E12: Argent | F12: 2 | G12: Or | H12: 2 | I12: Cuir | J12: 2 | K12: Fil | L12: 16 | Q12: =SUM( IFERROR(VLOOKUP(E12,MATERIAUX!$A$1:$D$27,4,FALSE)*F12,0), IFERROR(VLOOKUP(G12,MATERIAUX!$A$1:$D$27,4,FALSE)*H12,0), IFERROR(VLOOKUP(I12,MATERIAUX!$A$1:$D$27,4,FALSE)*J12,0), IFERROR(VLOOKUP(K12,MATERIAUX!$A$1:$D$27,4,FALSE)*L12,0), IFERROR(VLOOKUP(M12,MATERIAUX!$A$1:$D$27,4,FALSE)*N12,0), IFERROR(VLOOKUP(O12,MATERIAUX!$A$1:$D$27,4,FALSE)*P12,0) ) -> 39.333333
A13: Fine Clothes Aureate Death | B13: 100 | C13: =B13-Q13 -> 60.666667 | D13: =(C13/Q13) -> 1.5423729 | E13: Argent | F13: 2 | G13: Or | H13: 2 | I13: Cuir | J13: 2 | K13: Fil | L13: 16 | Q13: =SUM( IFERROR(VLOOKUP(E13,MATERIAUX!$A$1:$D$27,4,FALSE)*F13,0), IFERROR(VLOOKUP(G13,MATERIAUX!$A$1:$D$27,4,FALSE)*H13,0), IFERROR(VLOOKUP(I13,MATERIAUX!$A$1:$D$27,4,FALSE)*J13,0), IFERROR(VLOOKUP(K13,MATERIAUX!$A$1:$D$27,4,FALSE)*L13,0), IFERROR(VLOOKUP(M13,MATERIAUX!$A$1:$D$27,4,FALSE)*N13,0), IFERROR(VLOOKUP(O13,MATERIAUX!$A$1:$D$27,4,FALSE)*P13,0) ) -> 39.333333
A14: Fine Clothes Bardic | B14: 100 | C14: =B14-Q14 -> 60.666667 | D14: =(C14/Q14) -> 1.5423729 | E14: Argent | F14: 2 | G14: Or | H14: 2 | I14: Cuir | J14: 2 | K14: Fil | L14: 16 | Q14: =SUM( IFERROR(VLOOKUP(E14,MATERIAUX!$A$1:$D$27,4,FALSE)*F14,0), IFERROR(VLOOKUP(G14,MATERIAUX!$A$1:$D$27,4,FALSE)*H14,0), IFERROR(VLOOKUP(I14,MATERIAUX!$A$1:$D$27,4,FALSE)*J14,0), IFERROR(VLOOKUP(K14,MATERIAUX!$A$1:$D$27,4,FALSE)*L14,0), IFERROR(VLOOKUP(M14,MATERIAUX!$A$1:$D$27,4,FALSE)*N14,0), IFERROR(VLOOKUP(O14,MATERIAUX!$A$1:$D$27,4,FALSE)*P14,0) ) -> 39.333333
A15: Fine Clothes Blood Moon | B15: 100 | C15: =B15-Q15 -> 60.666667 | D15: =(C15/Q15) -> 1.5423729 | E15: Argent | F15: 2 | G15: Or | H15: 2 | I15: Cuir | J15: 2 | K15: Fil | L15: 16 | Q15: =SUM( IFERROR(VLOOKUP(E15,MATERIAUX!$A$1:$D$27,4,FALSE)*F15,0), IFERROR(VLOOKUP(G15,MATERIAUX!$A$1:$D$27,4,FALSE)*H15,0), IFERROR(VLOOKUP(I15,MATERIAUX!$A$1:$D$27,4,FALSE)*J15,0), IFERROR(VLOOKUP(K15,MATERIAUX!$A$1:$D$27,4,FALSE)*L15,0), IFERROR(VLOOKUP(M15,MATERIAUX!$A$1:$D$27,4,FALSE)*N15,0), IFERROR(VLOOKUP(O15,MATERIAUX!$A$1:$D$27,4,FALSE)*P15,0) ) -> 39.333333
A16: Fine Clothes Blood Pact | B16: 100 | C16: =B16-Q16 -> 60.666667 | D16: =(C16/Q16) -> 1.5423729 | E16: Argent | F16: 2 | G16: Or | H16: 2 | I16: Cuir | J16: 2 | K16: Fil | L16: 16 | Q16: =SUM( IFERROR(VLOOKUP(E16,MATERIAUX!$A$1:$D$27,4,FALSE)*F16,0), IFERROR(VLOOKUP(G16,MATERIAUX!$A$1:$D$27,4,FALSE)*H16,0), IFERROR(VLOOKUP(I16,MATERIAUX!$A$1:$D$27,4,FALSE)*J16,0), IFERROR(VLOOKUP(K16,MATERIAUX!$A$1:$D$27,4,FALSE)*L16,0), IFERROR(VLOOKUP(M16,MATERIAUX!$A$1:$D$27,4,FALSE)*N16,0), IFERROR(VLOOKUP(O16,MATERIAUX!$A$1:$D$27,4,FALSE)*P16,0) ) -> 39.333333
A17: Fine Clothes Blue Moon | B17: 100 | C17: =B17-Q17 -> 60.666667 | D17: =(C17/Q17) -> 1.5423729 | E17: Argent | F17: 2 | G17: Or | H17: 2 | I17: Cuir | J17: 2 | K17: Fil | L17: 16 | Q17: =SUM( IFERROR(VLOOKUP(E17,MATERIAUX!$A$1:$D$27,4,FALSE)*F17,0), IFERROR(VLOOKUP(G17,MATERIAUX!$A$1:$D$27,4,FALSE)*H17,0), IFERROR(VLOOKUP(I17,MATERIAUX!$A$1:$D$27,4,FALSE)*J17,0), IFERROR(VLOOKUP(K17,MATERIAUX!$A$1:$D$27,4,FALSE)*L17,0), IFERROR(VLOOKUP(M17,MATERIAUX!$A$1:$D$27,4,FALSE)*N17,0), IFERROR(VLOOKUP(O17,MATERIAUX!$A$1:$D$27,4,FALSE)*P17,0) ) -> 39.333333
A18: Fine Clothes Burnished | B18: 100 | C18: =B18-Q18 -> 60.666667 | D18: =(C18/Q18) -> 1.5423729 | E18: Argent | F18: 2 | G18: Or | H18: 2 | I18: Cuir | J18: 2 | K18: Fil | L18: 16 | Q18: =SUM( IFERROR(VLOOKUP(E18,MATERIAUX!$A$1:$D$27,4,FALSE)*F18,0), IFERROR(VLOOKUP(G18,MATERIAUX!$A$1:$D$27,4,FALSE)*H18,0), IFERROR(VLOOKUP(I18,MATERIAUX!$A$1:$D$27,4,FALSE)*J18,0), IFERROR(VLOOKUP(K18,MATERIAUX!$A$1:$D$27,4,FALSE)*L18,0), IFERROR(VLOOKUP(M18,MATERIAUX!$A$1:$D$27,4,FALSE)*N18,0), IFERROR(VLOOKUP(O18,MATERIAUX!$A$1:$D$27,4,FALSE)*P18,0) ) -> 39.333333
A19: Fine Clothes Charcoal | B19: 100 | C19: =B19-Q19 -> 60.666667 | D19: =(C19/Q19) -> 1.5423729 | E19: Argent | F19: 2 | G19: Or | H19: 2 | I19: Cuir | J19: 2 | K19: Fil | L19: 16 | Q19: =SUM( IFERROR(VLOOKUP(E19,MATERIAUX!$A$1:$D$27,4,FALSE)*F19,0), IFERROR(VLOOKUP(G19,MATERIAUX!$A$1:$D$27,4,FALSE)*H19,0), IFERROR(VLOOKUP(I19,MATERIAUX!$A$1:$D$27,4,FALSE)*J19,0), IFERROR(VLOOKUP(K19,MATERIAUX!$A$1:$D$27,4,FALSE)*L19,0), IFERROR(VLOOKUP(M19,MATERIAUX!$A$1:$D$27,4,FALSE)*N19,0), IFERROR(VLOOKUP(O19,MATERIAUX!$A$1:$D$27,4,FALSE)*P19,0) ) -> 39.333333
A20: Fine Clothes Darkmoon | B20: 100 | C20: =B20-Q20 -> 60.666667 | D20: =(C20/Q20) -> 1.5423729 | E20: Argent | F20: 2 | G20: Or | H20: 2 | I20: Cuir | J20: 2 | K20: Fil | L20: 16 | Q20: =SUM( IFERROR(VLOOKUP(E20,MATERIAUX!$A$1:$D$27,4,FALSE)*F20,0), IFERROR(VLOOKUP(G20,MATERIAUX!$A$1:$D$27,4,FALSE)*H20,0), IFERROR(VLOOKUP(I20,MATERIAUX!$A$1:$D$27,4,FALSE)*J20,0), IFERROR(VLOOKUP(K20,MATERIAUX!$A$1:$D$27,4,FALSE)*L20,0), IFERROR(VLOOKUP(M20,MATERIAUX!$A$1:$D$27,4,FALSE)*N20,0), IFERROR(VLOOKUP(O20,MATERIAUX!$A$1:$D$27,4,FALSE)*P20,0) ) -> 39.333333
A21: Fine Clothes Deepwood | B21: 100 | C21: =B21-Q21 -> 60.666667 | D21: =(C21/Q21) -> 1.5423729 | E21: Argent | F21: 2 | G21: Or | H21: 2 | I21: Cuir | J21: 2 | K21: Fil | L21: 16 | Q21: =SUM( IFERROR(VLOOKUP(E21,MATERIAUX!$A$1:$D$27,4,FALSE)*F21,0), IFERROR(VLOOKUP(G21,MATERIAUX!$A$1:$D$27,4,FALSE)*H21,0), IFERROR(VLOOKUP(I21,MATERIAUX!$A$1:$D$27,4,FALSE)*J21,0), IFERROR(VLOOKUP(K21,MATERIAUX!$A$1:$D$27,4,FALSE)*L21,0), IFERROR(VLOOKUP(M21,MATERIAUX!$A$1:$D$27,4,FALSE)*N21,0), IFERROR(VLOOKUP(O21,MATERIAUX!$A$1:$D$27,4,FALSE)*P21,0) ) -> 39.333333
A22: Fine Clothes Fuscia | B22: 100 | C22: =B22-Q22 -> 60.666667 | D22: =(C22/Q22) -> 1.5423729 | E22: Argent | F22: 2 | G22: Or | H22: 2 | I22: Cuir | J22: 2 | K22: Fil | L22: 16 | Q22: =SUM( IFERROR(VLOOKUP(E22,MATERIAUX!$A$1:$D$27,4,FALSE)*F22,0), IFERROR(VLOOKUP(G22,MATERIAUX!$A$1:$D$27,4,FALSE)*H22,0), IFERROR(VLOOKUP(I22,MATERIAUX!$A$1:$D$27,4,FALSE)*J22,0), IFERROR(VLOOKUP(K22,MATERIAUX!$A$1:$D$27,4,FALSE)*L22,0), IFERROR(VLOOKUP(M22,MATERIAUX!$A$1:$D$27,4,FALSE)*N22,0), IFERROR(VLOOKUP(O22,MATERIAUX!$A$1:$D$27,4,FALSE)*P22,0) ) -> 39.333333
A23: Fine Clothes Ilinalta | B23: 100 | C23: =B23-Q23 -> 60.666667 | D23: =(C23/Q23) -> 1.5423729 | E23: Argent | F23: 2 | G23: Or | H23: 2 | I23: Cuir | J23: 2 | K23: Fil | L23: 16 | Q23: =SUM( IFERROR(VLOOKUP(E23,MATERIAUX!$A$1:$D$27,4,FALSE)*F23,0), IFERROR(VLOOKUP(G23,MATERIAUX!$A$1:$D$27,4,FALSE)*H23,0), IFERROR(VLOOKUP(I23,MATERIAUX!$A$1:$D$27,4,FALSE)*J23,0), IFERROR(VLOOKUP(K23,MATERIAUX!$A$1:$D$27,4,FALSE)*L23,0), IFERROR(VLOOKUP(M23,MATERIAUX!$A$1:$D$27,4,FALSE)*N23,0), IFERROR(VLOOKUP(O23,MATERIAUX!$A$1:$D$27,4,FALSE)*P23,0) ) -> 39.333333
... A30: Fine Clothes Wolfsbane | B30: 100 | C30: =B30-Q30 -> 60.666667 | D30: =(C30/Q30) -> 1.5423729 | E30: Argent | F30: 2 | G30: Or | H30: 2 | I30: Cuir | J30: 2 | K30: Fil | L30: 16 | Q30: =SUM( IFERROR(VLOOKUP(E30,MATERIAUX!$A$1:$D$27,4,FALSE)*F30,0), IFERROR(VLOOKUP(G30,MATERIAUX!$A$1:$D$27,4,FALSE)*H30,0), IFERROR(VLOOKUP(I30,MATERIAUX!$A$1:$D$27,4,FALSE)*J30,0), IFERROR(VLOOKUP(K30,MATERIAUX!$A$1:$D$27,4,FALSE)*L30,0), IFERROR(VLOOKUP(M30,MATERIAUX!$A$1:$D$27,4,FALSE)*N30,0), IFERROR(VLOOKUP(O30,MATERIAUX!$A$1:$D$27,4,FALSE)*P30,0) ) -> 39.333333
A31: Habit de taverne | B31: 20 | C31: =B31-Q31 -> 18.666667 | D31: =(C31/Q31) -> 14 | E31: Fil | F31: 4 | Q31: =SUM( IFERROR(VLOOKUP(E31,MATERIAUX!$A$1:$D$27,4,FALSE)*F31,0), IFERROR(VLOOKUP(G31,MATERIAUX!$A$1:$D$27,4,FALSE)*H31,0), IFERROR(VLOOKUP(I31,MATERIAUX!$A$1:$D$27,4,FALSE)*J31,0), IFERROR(VLOOKUP(K31,MATERIAUX!$A$1:$D$27,4,FALSE)*L31,0), IFERROR(VLOOKUP(M31,MATERIAUX!$A$1:$D$27,4,FALSE)*N31,0), IFERROR(VLOOKUP(O31,MATERIAUX!$A$1:$D$27,4,FALSE)*P31,0) ) -> 1.3333333
A32: Heavy Quilted Surcoat 01 | B32: 40 | C32: =B32-Q32 -> 32.8 | D32: =(C32/Q32) -> 4.5555556 | E32: Cuir | F32: 2 | G32: Coton | H32: 12 | Q32: =SUM( IFERROR(VLOOKUP(E32,MATERIAUX!$A$1:$D$27,4,FALSE)*F32,0), IFERROR(VLOOKUP(G32,MATERIAUX!$A$1:$D$27,4,FALSE)*H32,0), IFERROR(VLOOKUP(I32,MATERIAUX!$A$1:$D$27,4,FALSE)*J32,0), IFERROR(VLOOKUP(K32,MATERIAUX!$A$1:$D$27,4,FALSE)*L32,0), IFERROR(VLOOKUP(M32,MATERIAUX!$A$1:$D$27,4,FALSE)*N32,0), IFERROR(VLOOKUP(O32,MATERIAUX!$A$1:$D$27,4,FALSE)*P32,0) ) -> 7.2
A33: Hooded Monk Tunic | B33: 20 | C33: =B33-Q33 -> 18.666667 | D33: =(C33/Q33) -> 14 | E33: Fil | F33: 4 | Q33: =SUM( IFERROR(VLOOKUP(E33,MATERIAUX!$A$1:$D$27,4,FALSE)*F33,0), IFERROR(VLOOKUP(G33,MATERIAUX!$A$1:$D$27,4,FALSE)*H33,0), IFERROR(VLOOKUP(I33,MATERIAUX!$A$1:$D$27,4,FALSE)*J33,0), IFERROR(VLOOKUP(K33,MATERIAUX!$A$1:$D$27,4,FALSE)*L33,0), IFERROR(VLOOKUP(M33,MATERIAUX!$A$1:$D$27,4,FALSE)*N33,0), IFERROR(VLOOKUP(O33,MATERIAUX!$A$1:$D$27,4,FALSE)*P33,0) ) -> 1.3333333
A34: Hooded Necromancer Robes | B34: 20 | C34: =B34-Q34 -> 18.666667 | D34: =(C34/Q34) -> 14 | E34: Fil | F34: 4 | Q34: =SUM( IFERROR(VLOOKUP(E34,MATERIAUX!$A$1:$D$27,4,FALSE)*F34,0), IFERROR(VLOOKUP(G34,MATERIAUX!$A$1:$D$27,4,FALSE)*H34,0), IFERROR(VLOOKUP(I34,MATERIAUX!$A$1:$D$27,4,FALSE)*J34,0), IFERROR(VLOOKUP(K34,MATERIAUX!$A$1:$D$27,4,FALSE)*L34,0), IFERROR(VLOOKUP(M34,MATERIAUX!$A$1:$D$27,4,FALSE)*N34,0), IFERROR(VLOOKUP(O34,MATERIAUX!$A$1:$D$27,4,FALSE)*P34,0) ) -> 1.3333333
A35: Monk Tunic | B35: 20 | C35: =B35-Q35 -> 18.666667 | D35: =(C35/Q35) -> 14 | E35: Fil | F35: 4 | Q35: =SUM( IFERROR(VLOOKUP(E35,MATERIAUX!$A$1:$D$27,4,FALSE)*F35,0), IFERROR(VLOOKUP(G35,MATERIAUX!$A$1:$D$27,4,FALSE)*H35,0), IFERROR(VLOOKUP(I35,MATERIAUX!$A$1:$D$27,4,FALSE)*J35,0), IFERROR(VLOOKUP(K35,MATERIAUX!$A$1:$D$27,4,FALSE)*L35,0), IFERROR(VLOOKUP(M35,MATERIAUX!$A$1:$D$27,4,FALSE)*N35,0), IFERROR(VLOOKUP(O35,MATERIAUX!$A$1:$D$27,4,FALSE)*P35,0) ) -> 1.3333333
A36: Necormancer Robes | B36: 20 | C36: =B36-Q36 -> 18.666667 | D36: =(C36/Q36) -> 14 | E36: Fil | F36: 4 | Q36: =SUM( IFERROR(VLOOKUP(E36,MATERIAUX!$A$1:$D$27,4,FALSE)*F36,0), IFERROR(VLOOKUP(G36,MATERIAUX!$A$1:$D$27,4,FALSE)*H36,0), IFERROR(VLOOKUP(I36,MATERIAUX!$A$1:$D$27,4,FALSE)*J36,0), IFERROR(VLOOKUP(K36,MATERIAUX!$A$1:$D$27,4,FALSE)*L36,0), IFERROR(VLOOKUP(M36,MATERIAUX!$A$1:$D$27,4,FALSE)*N36,0), IFERROR(VLOOKUP(O36,MATERIAUX!$A$1:$D$27,4,FALSE)*P36,0) ) -> 1.3333333
A37: Pantalon usé | B37: 10 | C37: =B37-Q37 -> 9.6666667 | D37: =(C37/Q37) -> 29 | E37: Fil | F37: 1 | Q37: =SUM( IFERROR(VLOOKUP(E37,MATERIAUX!$A$1:$D$27,4,FALSE)*F37,0), IFERROR(VLOOKUP(G37,MATERIAUX!$A$1:$D$27,4,FALSE)*H37,0), IFERROR(VLOOKUP(I37,MATERIAUX!$A$1:$D$27,4,FALSE)*J37,0), IFERROR(VLOOKUP(K37,MATERIAUX!$A$1:$D$27,4,FALSE)*L37,0), IFERROR(VLOOKUP(M37,MATERIAUX!$A$1:$D$27,4,FALSE)*N37,0), IFERROR(VLOOKUP(O37,MATERIAUX!$A$1:$D$27,4,FALSE)*P37,0) ) -> 0.33333333
A38: Quilted Surcoat 01 | B38: 40 | C38: =B38-Q38 -> 32.8 | D38: =(C38/Q38) -> 4.5555556 | E38: Coton | F38: 12 | G38: Cuir | H38: 2 | Q38: =SUM( IFERROR(VLOOKUP(E38,MATERIAUX!$A$1:$D$27,4,FALSE)*F38,0), IFERROR(VLOOKUP(G38,MATERIAUX!$A$1:$D$27,4,FALSE)*H38,0), IFERROR(VLOOKUP(I38,MATERIAUX!$A$1:$D$27,4,FALSE)*J38,0), IFERROR(VLOOKUP(K38,MATERIAUX!$A$1:$D$27,4,FALSE)*L38,0), IFERROR(VLOOKUP(M38,MATERIAUX!$A$1:$D$27,4,FALSE)*N38,0), IFERROR(VLOOKUP(O38,MATERIAUX!$A$1:$D$27,4,FALSE)*P38,0) ) -> 7.2
A39: Quilted Surcoat 02 | B39: 40 | C39: =B39-Q39 -> 32.8 | D39: =(C39/Q39) -> 4.5555556 | E39: Coton | F39: 12 | G39: Cuir | H39: 2 | Q39: =SUM( IFERROR(VLOOKUP(E39,MATERIAUX!$A$1:$D$27,4,FALSE)*F39,0), IFERROR(VLOOKUP(G39,MATERIAUX!$A$1:$D$27,4,FALSE)*H39,0), IFERROR(VLOOKUP(I39,MATERIAUX!$A$1:$D$27,4,FALSE)*J39,0), IFERROR(VLOOKUP(K39,MATERIAUX!$A$1:$D$27,4,FALSE)*L39,0), IFERROR(VLOOKUP(M39,MATERIAUX!$A$1:$D$27,4,FALSE)*N39,0), IFERROR(VLOOKUP(O39,MATERIAUX!$A$1:$D$27,4,FALSE)*P39,0) ) -> 7.2
A40: Quilted Tunic | B40: 40 | C40: =B40-Q40 -> 32.8 | D40: =(C40/Q40) -> 4.5555556 | E40: Coton | F40: 12 | G40: Cuir | H40: 2 | Q40: =SUM( IFERROR(VLOOKUP(E40,MATERIAUX!$A$1:$D$27,4,FALSE)*F40,0), IFERROR(VLOOKUP(G40,MATERIAUX!$A$1:$D$27,4,FALSE)*H40,0), IFERROR(VLOOKUP(I40,MATERIAUX!$A$1:$D$27,4,FALSE)*J40,0), IFERROR(VLOOKUP(K40,MATERIAUX!$A$1:$D$27,4,FALSE)*L40,0), IFERROR(VLOOKUP(M40,MATERIAUX!$A$1:$D$27,4,FALSE)*N40,0), IFERROR(VLOOKUP(O40,MATERIAUX!$A$1:$D$27,4,FALSE)*P40,0) ) -> 7.2
A41: Quilted Tunic and Green Robes | B41: 40 | C41: =B41-Q41 -> 32.8 | D41: =(C41/Q41) -> 4.5555556 | E41: Coton | F41: 12 | G41: Cuir | H41: 2 | Q41: =SUM( IFERROR(VLOOKUP(E41,MATERIAUX!$A$1:$D$27,4,FALSE)*F41,0), IFERROR(VLOOKUP(G41,MATERIAUX!$A$1:$D$27,4,FALSE)*H41,0), IFERROR(VLOOKUP(I41,MATERIAUX!$A$1:$D$27,4,FALSE)*J41,0), IFERROR(VLOOKUP(K41,MATERIAUX!$A$1:$D$27,4,FALSE)*L41,0), IFERROR(VLOOKUP(M41,MATERIAUX!$A$1:$D$27,4,FALSE)*N41,0), IFERROR(VLOOKUP(O41,MATERIAUX!$A$1:$D$27,4,FALSE)*P41,0) ) -> 7.2
A42: Quilted Tunic and White Robes | B42: 40 | C42: =B42-Q42 -> 32.8 | D42: =(C42/Q42) -> 4.5555556 | E42: Coton | F42: 12 | G42: Cuir | H42: 2 | Q42: =SUM( IFERROR(VLOOKUP(E42,MATERIAUX!$A$1:$D$27,4,FALSE)*F42,0), IFERROR(VLOOKUP(G42,MATERIAUX!$A$1:$D$27,4,FALSE)*H42,0), IFERROR(VLOOKUP(I42,MATERIAUX!$A$1:$D$27,4,FALSE)*J42,0), IFERROR(VLOOKUP(K42,MATERIAUX!$A$1:$D$27,4,FALSE)*L42,0), IFERROR(VLOOKUP(M42,MATERIAUX!$A$1:$D$27,4,FALSE)*N42,0), IFERROR(VLOOKUP(O42,MATERIAUX!$A$1:$D$27,4,FALSE)*P42,0) ) -> 7.2
A43: Quilted Tunic with Surcoat | B43: 40 | C43: =B43-Q43 -> 32.8 | D43: =(C43/Q43) -> 4.5555556 | E43: Coton | F43: 12 | G43: Cuir | H43: 2 | Q43: =SUM( IFERROR(VLOOKUP(E43,MATERIAUX!$A$1:$D$27,4,FALSE)*F43,0), IFERROR(VLOOKUP(G43,MATERIAUX!$A$1:$D$27,4,FALSE)*H43,0), IFERROR(VLOOKUP(I43,MATERIAUX!$A$1:$D$27,4,FALSE)*J43,0), IFERROR(VLOOKUP(K43,MATERIAUX!$A$1:$D$27,4,FALSE)*L43,0), IFERROR(VLOOKUP(M43,MATERIAUX!$A$1:$D$27,4,FALSE)*N43,0), IFERROR(VLOOKUP(O43,MATERIAUX!$A$1:$D$27,4,FALSE)*P43,0) ) -> 7.2
A44: Robe (Bleu, Moine, Grise, Marron, Noire, Rouge, Verte, usée) | B44: 20 | C44: =B44-Q44 -> 18.666667 | D44: =(C44/Q44) -> 14 | E44: Fil | F44: 4 | Q44: =SUM( IFERROR(VLOOKUP(E44,MATERIAUX!$A$1:$D$27,4,FALSE)*F44,0), IFERROR(VLOOKUP(G44,MATERIAUX!$A$1:$D$27,4,FALSE)*H44,0), IFERROR(VLOOKUP(I44,MATERIAUX!$A$1:$D$27,4,FALSE)*J44,0), IFERROR(VLOOKUP(K44,MATERIAUX!$A$1:$D$27,4,FALSE)*L44,0), IFERROR(VLOOKUP(M44,MATERIAUX!$A$1:$D$27,4,FALSE)*N44,0), IFERROR(VLOOKUP(O44,MATERIAUX!$A$1:$D$27,4,FALSE)*P44,0) ) -> 1.3333333
A45: Robe à Capuchon (Bleu, Moine, Grise, Marron, Noire, Rouge, Verte, usée) | B45: 20 | C45: =B45-Q45 -> 18.666667 | D45: =(C45/Q45) -> 14 | E45: Fil | F45: 4 | Q45: =SUM( IFERROR(VLOOKUP(E45,MATERIAUX!$A$1:$D$27,4,FALSE)*F45,0), IFERROR(VLOOKUP(G45,MATERIAUX!$A$1:$D$27,4,FALSE)*H45,0), IFERROR(VLOOKUP(I45,MATERIAUX!$A$1:$D$27,4,FALSE)*J45,0), IFERROR(VLOOKUP(K45,MATERIAUX!$A$1:$D$27,4,FALSE)*L45,0), IFERROR(VLOOKUP(M45,MATERIAUX!$A$1:$D$27,4,FALSE)*N45,0), IFERROR(VLOOKUP(O45,MATERIAUX!$A$1:$D$27,4,FALSE)*P45,0) ) -> 1.3333333
A46: Tablier de Forgeron | B46: 20 | C46: =B46-Q46 -> 16 | D46: =(C46/Q46) -> 4 | E46: Fil | F46: 3 | G46: Cuir | H46: 1 | Q46: =SUM( IFERROR(VLOOKUP(E46,MATERIAUX!$A$1:$D$27,4,FALSE)*F46,0), IFERROR(VLOOKUP(G46,MATERIAUX!$A$1:$D$27,4,FALSE)*H46,0), IFERROR(VLOOKUP(I46,MATERIAUX!$A$1:$D$27,4,FALSE)*J46,0), IFERROR(VLOOKUP(K46,MATERIAUX!$A$1:$D$27,4,FALSE)*L46,0), IFERROR(VLOOKUP(M46,MATERIAUX!$A$1:$D$27,4,FALSE)*N46,0), IFERROR(VLOOKUP(O46,MATERIAUX!$A$1:$D$27,4,FALSE)*P46,0) ) -> 4
...

Sheet MATERIAUX
A1: Objet | B1: Prix d'achat | C1: Quantitée | D1: Prix à l'unitée
A2: Lys des Cimes | B2: 1 | C2: 15 | D2: =B2/C2 -> 0.066666667
A3: Coton | B3: 1 | C3: 10 | D3: =B3/C3 -> 0.1
A4: Cuir | B4: 3 | C4: 1 | D4: =B4/C4 -> 3
A5: Bandes de cuir | B5: 3 | C5: 4 | D5: =B5/C5 -> 0.75
A6: Fer | B6: 3 | C6: 1 | D6: =B6/C6 -> 3
A7: Or | B7: 10 | C7: 1 | D7: =B7/C7 -> 10
A8: Vif Argent | B8: 50 | C8: 1 | D8: =B8/C8 -> 50
A9: Corindon raffiné | B9: 10 | C9: 1 | D9: =B9/C9 -> 10
A10: Argent | B10: 4 | C10: 1 | D10: =B10/C10 -> 4
A11: Dent de smilodon | B11: 3 | C11: 1 | D11: =B11/C11 -> 3
A12: Petit Bois | B12: 1 | C12: 1 | D12: =B12/C12 -> 1
A13: Fil | B13: 1 | C13: 3 | D13: =B13/C13 -> 0.33333333
A14: Lin | B14: 850 | C14: 1 | D14: =B14/C14 -> 850
